<sdf version='1.6'>
  <world name='default'>
    <light name='sun' type='directional'>
      <cast_shadows>1</cast_shadows>
      <pose frame=''>0 0 10 0 -0 0</pose>
      <diffuse>0.8 0.8 0.8 1</diffuse>
      <specular>0.2 0.2 0.2 1</specular>
      <attenuation>
        <range>1000</range>
        <constant>0.9</constant>
        <linear>0.01</linear>
        <quadratic>0.001</quadratic>
      </attenuation>
      <direction>-0.5 0.1 -0.9</direction>
    </light>
    <gravity>0 0 -9.8</gravity>
    <magnetic_field>6e-06 2.3e-05 -4.2e-05</magnetic_field>
    <atmosphere type='adiabatic'/>
    <physics name='default_physics' default='0' type='ode'>
      <max_step_size>0.001</max_step_size>
      <real_time_factor>1</real_time_factor>
      <real_time_update_rate>1000</real_time_update_rate>
    </physics>
    <scene>
      <ambient>0.4 0.4 0.4 1</ambient>
      <background>0.7 0.7 0.7 1</background>
      <shadows>1</shadows>
    </scene>
    <wind/>
    <spherical_coordinates>
      <surface_model>EARTH_WGS84</surface_model>
      <latitude_deg>0</latitude_deg>
      <longitude_deg>0</longitude_deg>
      <elevation>0</elevation>
      <heading_deg>0</heading_deg>
    </spherical_coordinates>
    <model name='heightmap'>
      <static>1</static>
      <pose frame=''>-0.02672 -1.1312 -95 0 -0 0</pose>
      <link name='link'>
        <collision name='collision'>
          <geometry>
            <mesh>
              <uri>model://heightmap/drøbak.dae</uri>
            </mesh>
          </geometry>
          <max_contacts>10</max_contacts>
          <surface>
            <contact>
              <ode/>
            </contact>
            <bounce/>
            <friction>
              <torsional>
                <ode/>
              </torsional>
              <ode/>
            </friction>
          </surface>
        </collision>
        <visual name='visual'>
          <geometry>
            <mesh>
              <uri>model://heightmap/drøbak.dae</uri>
            </mesh>
          </geometry>
          <material>
            <script>
              <uri>model://heightmap/materials/scripts</uri>
              <uri>model://heightmap/materials/textures</uri>
              <name>heightmap/ground</name>
            </script>
          </material>
        </visual>
        <self_collide>0</self_collide>
        <enable_wind>0</enable_wind>
        <kinematic>0</kinematic>
      </link>
    </model>
    <state world_name='default'>
      <sim_time>127 994000000</sim_time>
      <real_time>96 419629589</real_time>
      <wall_time>1587396318 418085779</wall_time>
      <iterations>94630</iterations>
      <model name='heightmap'>
        <pose frame=''>-0.02672 -1.1312 -95 0 -0 0</pose>
        <scale>1 1 1</scale>
        <link name='link'>
          <pose frame=''>-0.02672 -1.1312 -95 0 -0 0</pose>
          <velocity>0 0 0 0 -0 0</velocity>
          <acceleration>0 0 0 0 -0 0</acceleration>
          <wrench>0 0 0 0 -0 0</wrench>
        </link>
      </model>
      <model name='thorvald_ii'>
        <pose frame=''>-0.21645 -0.146712 1.78299 0.060129 -0.01802 0.055538</pose>
        <scale>1 1 1</scale>
        <link name='/base_link'>
          <pose frame=''>-0.21645 -0.146712 1.78299 0.060129 -0.01802 0.055538</pose>
          <velocity>-0.002809 0.009579 -0.17111 0.025628 -0.002903 0.000134</velocity>
          <acceleration>-0.082227 -0.034693 -1.30938 0.171315 0.044666 0.004509</acceleration>
          <wrench>-7.11923 -3.00373 -113.366 0 -0 0</wrench>
        </link>
        <link name='/leg0'>
          <pose frame=''>-0.749343 -0.473299 1.95562 0.060129 -0.018021 0.055544</pose>
          <velocity>-0.003266 0.005051 -0.18103 0.025604 -0.0029 0.000134</velocity>
          <acceleration>-0.09874 0.034524 -1.33673 0.185402 -0.003165 0.009964</acceleration>
          <wrench>-1.54429 0.539956 -20.9065 0 -0 0</wrench>
        </link>
        <link name='/leg1'>
          <pose frame=''>0.342793 -0.412582 1.97533 0.060129 -0.018021 0.055552</pose>
          <velocity>-0.00333 0.004705 -0.176303 0.025617 -0.00289 -1.4e-05</velocity>
          <acceleration>-0.098198 0.036622 -1.37298 0.18541 -0.003192 0.009893</acceleration>
          <wrench>-1.53582 0.572768 -21.4735 0 -0 0</wrench>
        </link>
        <link name='/leg2'>
          <pose frame=''>0.310593 0.155477 2.00958 0.060129 -0.018021 0.055552</pose>
          <velocity>-0.003505 0.003835 -0.161832 0.025625 -0.002888 -1.8e-05</velocity>
          <acceleration>-0.099581 0.030674 -1.27463 0.185457 -0.003182 0.009946</acceleration>
          <wrench>-1.55745 0.479749 -19.9353 0 -0 0</wrench>
        </link>
        <link name='/leg3'>
          <pose frame=''>-0.781542 0.094759 1.98986 0.060129 -0.018021 0.05555</pose>
          <velocity>-0.003442 0.004218 -0.16656 0.02564 -0.002913 3.4e-05</velocity>
          <acceleration>-0.100119 0.028532 -1.23839 0.185413 -0.003121 0.010057</acceleration>
          <wrench>-1.56585 0.446243 -19.3684 0 -0 0</wrench>
        </link>
        <link name='/wheel0_link'>
          <pose frame=''>-0.749343 -0.4733 1.95562 1.51065 -0.028078 -3.08327</pose>
          <velocity>-0.003261 0.004875 -0.181039 0.026866 -0.029556 -0.001434</velocity>
          <acceleration>-0.098731 0.034387 -1.33674 0.205982 -1.01599 -0.046459</acceleration>
          <wrench>-0.592388 0.206323 -8.02043 0 -0 0</wrench>
        </link>
        <link name='/wheel1_link'>
          <pose frame=''>0.342793 -0.412581 1.97533 1.37069 -1.26372 -2.89398</pose>
          <velocity>-0.003322 0.00458 -0.176309 0.026999 -0.029513 -0.00144</velocity>
          <acceleration>-0.09818 0.036437 -1.37299 0.146373 -1.01893 -0.051533</acceleration>
          <wrench>-0.58908 0.218622 -8.23797 0 -0 0</wrench>
        </link>
        <link name='/wheel2_link'>
          <pose frame=''>0.310593 0.155478 2.00958 1.37096 -1.26328 -2.89427</pose>
          <velocity>-0.003495 0.003754 -0.161837 0.027033 -0.029314 -0.001436</velocity>
          <acceleration>-0.099589 0.030803 -1.27463 0.146567 -1.0186 -0.051581</acceleration>
          <wrench>-0.597534 0.18482 -7.64776 0 -0 0</wrench>
        </link>
        <link name='/wheel3_link'>
          <pose frame=''>-0.781543 0.094762 1.98986 1.50923 -0.216936 -3.07169</pose>
          <velocity>-0.003425 0.004048 -0.166565 0.026899 -0.02931 -0.001453</velocity>
          <acceleration>-0.100136 0.028727 -1.23838 0.201385 -1.01528 -0.057174</acceleration>
          <wrench>-0.600817 0.172362 -7.43025 0 -0 0</wrench>
        </link>
      </model>
      <light name='sun'>
        <pose frame=''>0 0 10 0 -0 0</pose>
      </light>
    </state>
    <gui fullscreen='0'>
      <camera name='user_camera'>
        <pose frame=''>-613.357 -302.444 326.421 0 0.439643 0.436187</pose>
        <view_controller>orbit</view_controller>
        <projection_type>perspective</projection_type>
      </camera>
    </gui>
    <model name='thorvald_ii'>
      <link name='/base_link'>
        <pose frame=''>0 0 0 0 -0 0</pose>
        <inertial>
          <pose frame=''>-0.005197 0 0.594713 0 -0 0</pose>
          <mass>86.58</mass>
          <inertia>
            <ixx>55.2146</ixx>
            <ixy>0.32325</ixy>
            <ixz>-0.0426303</ixz>
            <iyy>69.6949</iyy>
            <iyz>-3.26441e-09</iyz>
            <izz>56.1921</izz>
          </inertia>
        </inertial>
        <collision name='/base_link_fixed_joint_lump__/top0_collision'>
          <pose frame=''>-0.547 -0.285 0.65 0 -0 -3.14159</pose>
          <geometry>
            <mesh>
              <scale>1 1 1</scale>
              <uri>/opt/ros/kinetic/share/thorvald_model/meshes/tower_modules/DUMMY-TOWER-M.stl</uri>
            </mesh>
          </geometry>
          <max_contacts>10</max_contacts>
          <surface>
            <contact>
              <ode/>
            </contact>
            <bounce/>
            <friction>
              <torsional>
                <ode/>
              </torsional>
              <ode/>
            </friction>
          </surface>
        </collision>
        <collision name='/base_link_fixed_joint_lump__/top1_collision_1'>
          <pose frame=''>0.547 -0.285 0.65 0 -0 0</pose>
          <geometry>
            <mesh>
              <scale>1 1 1</scale>
              <uri>/opt/ros/kinetic/share/thorvald_model/meshes/tower_modules/DUMMY-TOWER-MIRROR-M.stl</uri>
            </mesh>
          </geometry>
          <max_contacts>10</max_contacts>
          <surface>
            <contact>
              <ode/>
            </contact>
            <bounce/>
            <friction>
              <torsional>
                <ode/>
              </torsional>
              <ode/>
            </friction>
          </surface>
        </collision>
        <collision name='/base_link_fixed_joint_lump__/top2_collision_2'>
          <pose frame=''>0.547 0.285 0.65 0 -0 0</pose>
          <geometry>
            <mesh>
              <scale>1 1 1</scale>
              <uri>/opt/ros/kinetic/share/thorvald_model/meshes/tower_modules/DUMMY-TOWER-M.stl</uri>
            </mesh>
          </geometry>
          <max_contacts>10</max_contacts>
          <surface>
            <contact>
              <ode/>
            </contact>
            <bounce/>
            <friction>
              <torsional>
                <ode/>
              </torsional>
              <ode/>
            </friction>
          </surface>
        </collision>
        <collision name='/base_link_fixed_joint_lump__/top3_collision_3'>
          <pose frame=''>-0.547 0.285 0.65 0 -0 -3.14159</pose>
          <geometry>
            <mesh>
              <scale>1 1 1</scale>
              <uri>/opt/ros/kinetic/share/thorvald_model/meshes/tower_modules/DUMMY-TOWER-MIRROR-M.stl</uri>
            </mesh>
          </geometry>
          <max_contacts>10</max_contacts>
          <surface>
            <contact>
              <ode/>
            </contact>
            <bounce/>
            <friction>
              <torsional>
                <ode/>
              </torsional>
              <ode/>
            </friction>
          </surface>
        </collision>
        <collision name='/base_link_fixed_joint_lump__/bat0_collision_4'>
          <pose frame=''>0 0.285 0.72 0 -0 -3.14159</pose>
          <geometry>
            <mesh>
              <scale>1 1 1</scale>
              <uri>/opt/ros/kinetic/share/thorvald_model/meshes/bat_enc_modules/836586-1-DUMMY-RevA.stl</uri>
            </mesh>
          </geometry>
          <max_contacts>10</max_contacts>
          <surface>
            <contact>
              <ode/>
            </contact>
            <bounce/>
            <friction>
              <torsional>
                <ode/>
              </torsional>
              <ode/>
            </friction>
          </surface>
        </collision>
        <collision name='/base_link_fixed_joint_lump__/bat1_collision_5'>
          <pose frame=''>0 -0.285 0.72 0 -0 0</pose>
          <geometry>
            <mesh>
              <scale>1 1 1</scale>
              <uri>/opt/ros/kinetic/share/thorvald_model/meshes/bat_enc_modules/836586-1-DUMMY-RevA.stl</uri>
            </mesh>
          </geometry>
          <max_contacts>10</max_contacts>
          <surface>
            <contact>
              <ode/>
            </contact>
            <bounce/>
            <friction>
              <torsional>
                <ode/>
              </torsional>
              <ode/>
            </friction>
          </surface>
        </collision>
        <collision name='/base_link_fixed_joint_lump__/pipe0_1_collision_6'>
          <pose frame=''>0 -0.2925 0.575 1.5708 0 -1.58844</pose>
          <geometry>
            <cylinder>
              <length>0.850132</length>
              <radius>0.02</radius>
            </cylinder>
          </geometry>
          <max_contacts>10</max_contacts>
          <surface>
            <contact>
              <ode/>
            </contact>
            <bounce/>
            <friction>
              <torsional>
                <ode/>
              </torsional>
              <ode/>
            </friction>
          </surface>
        </collision>
        <collision name='/base_link_fixed_joint_lump__/pipe0_2_collision_7'>
          <pose frame=''>0 -0.2925 0.725 1.5708 0 -1.58844</pose>
          <geometry>
            <cylinder>
              <length>0.850132</length>
              <radius>0.02</radius>
            </cylinder>
          </geometry>
          <max_contacts>10</max_contacts>
          <surface>
            <contact>
              <ode/>
            </contact>
            <bounce/>
            <friction>
              <torsional>
                <ode/>
              </torsional>
              <ode/>
            </friction>
          </surface>
        </collision>
        <collision name='/base_link_fixed_joint_lump__/pipe1_1_collision_8'>
          <pose frame=''>0.425 0.0075 0.575 1.5708 -0 0</pose>
          <geometry>
            <cylinder>
              <length>0.585</length>
              <radius>0.02</radius>
            </cylinder>
          </geometry>
          <max_contacts>10</max_contacts>
          <surface>
            <contact>
              <ode/>
            </contact>
            <bounce/>
            <friction>
              <torsional>
                <ode/>
              </torsional>
              <ode/>
            </friction>
          </surface>
        </collision>
        <collision name='/base_link_fixed_joint_lump__/pipe1_2_collision_9'>
          <pose frame=''>0.425 0.0075 0.725 1.5708 -0 0</pose>
          <geometry>
            <cylinder>
              <length>0.585</length>
              <radius>0.02</radius>
            </cylinder>
          </geometry>
          <max_contacts>10</max_contacts>
          <surface>
            <contact>
              <ode/>
            </contact>
            <bounce/>
            <friction>
              <torsional>
                <ode/>
              </torsional>
              <ode/>
            </friction>
          </surface>
        </collision>
        <collision name='/base_link_fixed_joint_lump__/pipe2_1_collision_10'>
          <pose frame=''>0 0.2925 0.575 1.5708 -0 1.55315</pose>
          <geometry>
            <cylinder>
              <length>0.850132</length>
              <radius>0.02</radius>
            </cylinder>
          </geometry>
          <max_contacts>10</max_contacts>
          <surface>
            <contact>
              <ode/>
            </contact>
            <bounce/>
            <friction>
              <torsional>
                <ode/>
              </torsional>
              <ode/>
            </friction>
          </surface>
        </collision>
        <collision name='/base_link_fixed_joint_lump__/pipe2_2_collision_11'>
          <pose frame=''>0 0.2925 0.725 1.5708 -0 1.55315</pose>
          <geometry>
            <cylinder>
              <length>0.850132</length>
              <radius>0.02</radius>
            </cylinder>
          </geometry>
          <max_contacts>10</max_contacts>
          <surface>
            <contact>
              <ode/>
            </contact>
            <bounce/>
            <friction>
              <torsional>
                <ode/>
              </torsional>
              <ode/>
            </friction>
          </surface>
        </collision>
        <collision name='/base_link_fixed_joint_lump__/pipe3_1_collision_12'>
          <pose frame=''>-0.425 -0.0075 0.575 1.5708 -0 3.14159</pose>
          <geometry>
            <cylinder>
              <length>0.585</length>
              <radius>0.02</radius>
            </cylinder>
          </geometry>
          <max_contacts>10</max_contacts>
          <surface>
            <contact>
              <ode/>
            </contact>
            <bounce/>
            <friction>
              <torsional>
                <ode/>
              </torsional>
              <ode/>
            </friction>
          </surface>
        </collision>
        <collision name='/base_link_fixed_joint_lump__/pipe3_2_collision_13'>
          <pose frame=''>-0.425 -0.0075 0.725 1.5708 -0 3.14159</pose>
          <geometry>
            <cylinder>
              <length>0.585</length>
              <radius>0.02</radius>
            </cylinder>
          </geometry>
          <max_contacts>10</max_contacts>
          <surface>
            <contact>
              <ode/>
            </contact>
            <bounce/>
            <friction>
              <torsional>
                <ode/>
              </torsional>
              <ode/>
            </friction>
          </surface>
        </collision>
        <collision name='/base_link_fixed_joint_lump__/hokuyo_collision_14'>
          <pose frame=''>0.7025 0.005 0.66 0 -0 0</pose>
          <geometry>
            <box>
              <size>0.1 0.1 0.1</size>
            </box>
          </geometry>
          <surface>
            <contact>
              <ode/>
            </contact>
            <friction>
              <ode/>
              <torsional>
                <ode/>
              </torsional>
            </friction>
            <bounce/>
          </surface>
          <max_contacts>10</max_contacts>
        </collision>
        <collision name='/base_link_fixed_joint_lump__/sprayer_collision_15'>
          <pose frame=''>-0.45 0 0.5 0 -0 0</pose>
          <geometry>
            <box>
              <size>0.1 0.1 0.1</size>
            </box>
          </geometry>
          <surface>
            <contact>
              <ode/>
            </contact>
            <friction>
              <ode/>
              <torsional>
                <ode/>
              </torsional>
            </friction>
            <bounce/>
          </surface>
          <max_contacts>10</max_contacts>
        </collision>
        <collision name='/base_link_fixed_joint_lump__box_collision_collision_16'>
          <pose frame=''>0.8 0 1.75 0 1.0472 0</pose>
          <geometry>
            <box>
              <size>0.1 0.25 0.06</size>
            </box>
          </geometry>
          <max_contacts>10</max_contacts>
          <surface>
            <contact>
              <ode/>
            </contact>
            <bounce/>
            <friction>
              <torsional>
                <ode/>
              </torsional>
              <ode/>
            </friction>
          </surface>
        </collision>
        <visual name='/base_link_fixed_joint_lump__/top0_visual'>
          <pose frame=''>-0.547 -0.285 0.65 0 -0 -3.14159</pose>
          <geometry>
            <mesh>
              <scale>1 1 1</scale>
              <uri>/opt/ros/kinetic/share/thorvald_model/meshes/tower_modules/DUMMY-TOWER-M.stl</uri>
            </mesh>
          </geometry>
        </visual>
        <visual name='/base_link_fixed_joint_lump__/top1_visual_1'>
          <pose frame=''>0.547 -0.285 0.65 0 -0 0</pose>
          <geometry>
            <mesh>
              <scale>1 1 1</scale>
              <uri>/opt/ros/kinetic/share/thorvald_model/meshes/tower_modules/DUMMY-TOWER-MIRROR-M.stl</uri>
            </mesh>
          </geometry>
        </visual>
        <visual name='/base_link_fixed_joint_lump__/top2_visual_2'>
          <pose frame=''>0.547 0.285 0.65 0 -0 0</pose>
          <geometry>
            <mesh>
              <scale>1 1 1</scale>
              <uri>/opt/ros/kinetic/share/thorvald_model/meshes/tower_modules/DUMMY-TOWER-M.stl</uri>
            </mesh>
          </geometry>
        </visual>
        <visual name='/base_link_fixed_joint_lump__/top3_visual_3'>
          <pose frame=''>-0.547 0.285 0.65 0 -0 -3.14159</pose>
          <geometry>
            <mesh>
              <scale>1 1 1</scale>
              <uri>/opt/ros/kinetic/share/thorvald_model/meshes/tower_modules/DUMMY-TOWER-MIRROR-M.stl</uri>
            </mesh>
          </geometry>
        </visual>
        <visual name='/base_link_fixed_joint_lump__/bat0_visual_4'>
          <pose frame=''>0 0.285 0.72 0 -0 -3.14159</pose>
          <geometry>
            <mesh>
              <scale>1 1 1</scale>
              <uri>/opt/ros/kinetic/share/thorvald_model/meshes/bat_enc_modules/836586-1-DUMMY-RevA.stl</uri>
            </mesh>
          </geometry>
        </visual>
        <visual name='/base_link_fixed_joint_lump__/bat1_visual_5'>
          <pose frame=''>0 -0.285 0.72 0 -0 0</pose>
          <geometry>
            <mesh>
              <scale>1 1 1</scale>
              <uri>/opt/ros/kinetic/share/thorvald_model/meshes/bat_enc_modules/836586-1-DUMMY-RevA.stl</uri>
            </mesh>
          </geometry>
        </visual>
        <visual name='/base_link_fixed_joint_lump__/corner0_visual_6'>
          <pose frame=''>-0.368 -0.285 0.65 0 -0 3.14159</pose>
          <geometry>
            <cylinder>
              <length>0.15</length>
              <radius>0.02</radius>
            </cylinder>
          </geometry>
        </visual>
        <visual name='/base_link_fixed_joint_lump__/corner0_1_visual_7'>
          <pose frame=''>-0.425 -0.285 0.575 0 -0 3.14159</pose>
          <geometry>
            <mesh>
              <scale>1 1 1</scale>
              <uri>/opt/ros/kinetic/share/thorvald_model/meshes/clamps/DUMMY-T-BRACKET.stl</uri>
            </mesh>
          </geometry>
        </visual>
        <visual name='/base_link_fixed_joint_lump__/corner0_2_visual_8'>
          <pose frame=''>-0.425 -0.285 0.725 0 -0 3.14159</pose>
          <geometry>
            <mesh>
              <scale>1 1 1</scale>
              <uri>/opt/ros/kinetic/share/thorvald_model/meshes/clamps/DUMMY-T-BRACKET.stl</uri>
            </mesh>
          </geometry>
        </visual>
        <visual name='/base_link_fixed_joint_lump__/corner1_visual_9'>
          <pose frame=''>0.368 -0.285 0.65 0 -0 0</pose>
          <geometry>
            <cylinder>
              <length>0.15</length>
              <radius>0.02</radius>
            </cylinder>
          </geometry>
        </visual>
        <visual name='/base_link_fixed_joint_lump__/corner1_1_visual_10'>
          <pose frame=''>0.425 -0.285 0.575 0 -0 0</pose>
          <geometry>
            <mesh>
              <scale>1 1 1</scale>
              <uri>/opt/ros/kinetic/share/thorvald_model/meshes/clamps/DUMMY-T-BRACKET.stl</uri>
            </mesh>
          </geometry>
        </visual>
        <visual name='/base_link_fixed_joint_lump__/corner1_2_visual_11'>
          <pose frame=''>0.425 -0.285 0.725 0 -0 0</pose>
          <geometry>
            <mesh>
              <scale>1 1 1</scale>
              <uri>/opt/ros/kinetic/share/thorvald_model/meshes/clamps/DUMMY-T-BRACKET.stl</uri>
            </mesh>
          </geometry>
        </visual>
        <visual name='/base_link_fixed_joint_lump__/corner2_visual_12'>
          <pose frame=''>0.368 0.285 0.65 0 -0 0</pose>
          <geometry>
            <cylinder>
              <length>0.15</length>
              <radius>0.02</radius>
            </cylinder>
          </geometry>
        </visual>
        <visual name='/base_link_fixed_joint_lump__/corner2_1_visual_13'>
          <pose frame=''>0.425 0.285 0.575 0 -0 0</pose>
          <geometry>
            <mesh>
              <scale>1 1 1</scale>
              <uri>/opt/ros/kinetic/share/thorvald_model/meshes/clamps/DUMMY-T-BRACKET.stl</uri>
            </mesh>
          </geometry>
        </visual>
        <visual name='/base_link_fixed_joint_lump__/corner2_2_visual_14'>
          <pose frame=''>0.425 0.285 0.725 0 -0 0</pose>
          <geometry>
            <mesh>
              <scale>1 1 1</scale>
              <uri>/opt/ros/kinetic/share/thorvald_model/meshes/clamps/DUMMY-T-BRACKET.stl</uri>
            </mesh>
          </geometry>
        </visual>
        <visual name='/base_link_fixed_joint_lump__/corner3_visual_15'>
          <pose frame=''>-0.368 0.285 0.65 0 -0 3.14159</pose>
          <geometry>
            <cylinder>
              <length>0.15</length>
              <radius>0.02</radius>
            </cylinder>
          </geometry>
        </visual>
        <visual name='/base_link_fixed_joint_lump__/corner3_1_visual_16'>
          <pose frame=''>-0.425 0.285 0.575 0 -0 3.14159</pose>
          <geometry>
            <mesh>
              <scale>1 1 1</scale>
              <uri>/opt/ros/kinetic/share/thorvald_model/meshes/clamps/DUMMY-T-BRACKET.stl</uri>
            </mesh>
          </geometry>
        </visual>
        <visual name='/base_link_fixed_joint_lump__/corner3_2_visual_17'>
          <pose frame=''>-0.425 0.285 0.725 0 -0 3.14159</pose>
          <geometry>
            <mesh>
              <scale>1 1 1</scale>
              <uri>/opt/ros/kinetic/share/thorvald_model/meshes/clamps/DUMMY-T-BRACKET.stl</uri>
            </mesh>
          </geometry>
        </visual>
        <visual name='/base_link_fixed_joint_lump__/pipe0_1_visual_18'>
          <pose frame=''>0 -0.2925 0.575 1.5708 0 -1.58844</pose>
          <geometry>
            <cylinder>
              <length>0.850132</length>
              <radius>0.02</radius>
            </cylinder>
          </geometry>
        </visual>
        <visual name='/base_link_fixed_joint_lump__/pipe0_2_visual_19'>
          <pose frame=''>0 -0.2925 0.725 1.5708 0 -1.58844</pose>
          <geometry>
            <cylinder>
              <length>0.850132</length>
              <radius>0.02</radius>
            </cylinder>
          </geometry>
        </visual>
        <visual name='/base_link_fixed_joint_lump__/pipe1_1_visual_20'>
          <pose frame=''>0.425 0.0075 0.575 1.5708 -0 0</pose>
          <geometry>
            <cylinder>
              <length>0.585</length>
              <radius>0.02</radius>
            </cylinder>
          </geometry>
        </visual>
        <visual name='/base_link_fixed_joint_lump__/pipe1_2_visual_21'>
          <pose frame=''>0.425 0.0075 0.725 1.5708 -0 0</pose>
          <geometry>
            <cylinder>
              <length>0.585</length>
              <radius>0.02</radius>
            </cylinder>
          </geometry>
        </visual>
        <visual name='/base_link_fixed_joint_lump__/pipe2_1_visual_22'>
          <pose frame=''>0 0.2925 0.575 1.5708 -0 1.55315</pose>
          <geometry>
            <cylinder>
              <length>0.850132</length>
              <radius>0.02</radius>
            </cylinder>
          </geometry>
        </visual>
        <visual name='/base_link_fixed_joint_lump__/pipe2_2_visual_23'>
          <pose frame=''>0 0.2925 0.725 1.5708 -0 1.55315</pose>
          <geometry>
            <cylinder>
              <length>0.850132</length>
              <radius>0.02</radius>
            </cylinder>
          </geometry>
        </visual>
        <visual name='/base_link_fixed_joint_lump__/pipe3_1_visual_24'>
          <pose frame=''>-0.425 -0.0075 0.575 1.5708 -0 3.14159</pose>
          <geometry>
            <cylinder>
              <length>0.585</length>
              <radius>0.02</radius>
            </cylinder>
          </geometry>
        </visual>
        <visual name='/base_link_fixed_joint_lump__/pipe3_2_visual_25'>
          <pose frame=''>-0.425 -0.0075 0.725 1.5708 -0 3.14159</pose>
          <geometry>
            <cylinder>
              <length>0.585</length>
              <radius>0.02</radius>
            </cylinder>
          </geometry>
        </visual>
        <visual name='/base_link_fixed_joint_lump__/hokuyo_visual_26'>
          <pose frame=''>0.7025 0.005 0.66 0 -0 0</pose>
          <geometry>
            <mesh>
              <scale>1 1 1</scale>
              <uri>/opt/ros/kinetic/share/thorvald_model/meshes/hokuyo/hokuyo.dae</uri>
            </mesh>
          </geometry>
          <material>
            <script>
              <uri>__default__</uri>
              <name>__default__</name>
            </script>
          </material>
        </visual>
        <visual name='/base_link_fixed_joint_lump__/sprayer_visual_27'>
          <pose frame=''>-0.45 0 0.5 0 -0 0</pose>
          <geometry>
            <box>
              <size>0.1 0.1 0.1</size>
            </box>
          </geometry>
          <material>
            <script>
              <name>Gazebo/Orange</name>
              <uri>file://media/materials/scripts/gazebo.material</uri>
            </script>
          </material>
        </visual>
        <visual name='/base_link_fixed_joint_lump__kinect2_link_visual_28'>
          <pose frame=''>0.8 0 1.75 1e-06 -1.0472 3.14159</pose>
          <geometry>
            <mesh>
              <scale>1 1 1</scale>
              <uri>/opt/ros/kinetic/share/kinect2_description/meshes/sensors/kinect2.dae</uri>
            </mesh>
          </geometry>
          <material>
            <script>
              <uri>__default__</uri>
              <name>__default__</name>
            </script>
          </material>
        </visual>
        <velocity_decay/>
        <sensor name='hokuyo_sensor' type='ray'>
          <visualize>0</visualize>
          <update_rate>40</update_rate>
          <always_on>1</always_on>
          <ray>
            <scan>
              <horizontal>
                <samples>720</samples>
                <resolution>1</resolution>
                <min_angle>-1.5708</min_angle>
                <max_angle>1.5708</max_angle>
              </horizontal>
              <vertical>
                <samples>1</samples>
                <min_angle>0</min_angle>
                <max_angle>0</max_angle>
              </vertical>
            </scan>
            <range>
              <min>0.1</min>
              <max>30</max>
              <resolution>0.01</resolution>
            </range>
            <noise>
              <type>gaussian</type>
              <mean>0</mean>
              <stddev>0.01</stddev>
            </noise>
          </ray>
          <plugin name='hokuyo_node' filename='libgazebo_ros_laser.so'>
            <topicName>scan</topicName>
            <frameName>hokuyo</frameName>
            <robotNamespace>/</robotNamespace>
          </plugin>
          <pose frame=''>0.7025 0.005 0.66 0 -0 0</pose>
        </sensor>
        <velocity_decay/>
        <gravity>1</gravity>
        <velocity_decay/>
        <sensor name='kinect2_camera' type='camera'>
          <always_on>1</always_on>
          <update_rate>10</update_rate>
          <camera name='kinect2_camera'>
            <horizontal_fov>1.46708</horizontal_fov>
            <image>
              <width>1920</width>
              <height>1080</height>
              <format>R8G8B8</format>
            </image>
            <clip>
              <near>0.02</near>
              <far>10</far>
            </clip>
            <noise>
              <type>gaussian</type>
              <mean>0</mean>
              <stddev>0.007</stddev>
            </noise>
          </camera>
          <plugin name='kinect2_camera_controller' filename='libgazebo_ros_camera.so'>
            <alwaysOn>true</alwaysOn>
            <updateRate>10.0</updateRate>
            <cameraName>kinect2_camera</cameraName>
            <imageTopicName>rgb/image_color_rect</imageTopicName>
            <cameraInfoTopicName>rgb/camera_info</cameraInfoTopicName>
            <frameName>kinect2_rgb_optical_frame</frameName>
            <baseline>0.1</baseline>
            <distortionK1>0.0</distortionK1>
            <distortionK2>0.0</distortionK2>
            <distortionK3>0.0</distortionK3>
            <distortionT1>0.0</distortionT1>
            <distortionT2>0.0</distortionT2>
            <robotNamespace>/</robotNamespace>
          </plugin>
          <pose frame=''>0.8 0 1.75 0 1.0472 0</pose>
        </sensor>
        <self_collide>0</self_collide>
        <enable_wind>0</enable_wind>
        <kinematic>0</kinematic>
      </link>
      <link name='/leg0'>
        <pose frame=''>-0.547 -0.285 0.2 0 -0 0</pose>
        <inertial>
          <pose frame=''>0 0 0 0 -0 0</pose>
          <mass>15.64</mass>
          <inertia>
            <ixx>6.15</ixx>
            <ixy>1.31</ixy>
            <ixz>0.218</ixz>
            <iyy>1.386</iyy>
            <iyz>0.873</iyz>
            <izz>6.098</izz>
          </inertia>
        </inertial>
        <collision name='/leg0_collision'>
          <pose frame=''>0 0 0 0 -0 -3.14159</pose>
          <geometry>
            <mesh>
              <scale>1 1 1</scale>
              <uri>/opt/ros/kinetic/share/thorvald_model/meshes/drive_modules/836745-5-DUMMY-RevA.stl</uri>
            </mesh>
          </geometry>
          <max_contacts>10</max_contacts>
          <surface>
            <contact>
              <ode/>
            </contact>
            <bounce/>
            <friction>
              <torsional>
                <ode/>
              </torsional>
              <ode/>
            </friction>
          </surface>
        </collision>
        <visual name='/leg0_visual'>
          <pose frame=''>0 0 0 0 -0 -3.14159</pose>
          <geometry>
            <mesh>
              <scale>1 1 1</scale>
              <uri>/opt/ros/kinetic/share/thorvald_model/meshes/drive_modules/836745-5-DUMMY-RevA.stl</uri>
            </mesh>
          </geometry>
        </visual>
        <self_collide>0</self_collide>
        <enable_wind>0</enable_wind>
        <kinematic>0</kinematic>
      </link>
      <joint name='/steering0' type='revolute'>
        <child>/leg0</child>
        <parent>/base_link</parent>
        <axis>
          <xyz>0 0 1</xyz>
          <limit>
            <lower>-1e+16</lower>
            <upper>1e+16</upper>
          </limit>
          <dynamics>
            <spring_reference>0</spring_reference>
            <spring_stiffness>0</spring_stiffness>
          </dynamics>
          <use_parent_model_frame>1</use_parent_model_frame>
        </axis>
      </joint>
      <link name='/wheel0_link'>
        <pose frame=''>-0.547 -0.285 0.2 -1.5708 0 0</pose>
        <inertial>
          <pose frame=''>0 0 0 0 -0 0</pose>
          <mass>6</mass>
          <inertia>
            <ixx>0.874</ixx>
            <ixy>0</ixy>
            <ixz>0</ixz>
            <iyy>1.504</iyy>
            <iyz>0</iyz>
            <izz>0.874</izz>
          </inertia>
        </inertial>
        <collision name='/wheel0_link_collision'>
          <pose frame=''>0 0 0 0 -0 0</pose>
          <geometry>
            <cylinder>
              <length>0.16</length>
              <radius>0.2</radius>
            </cylinder>
          </geometry>
          <surface>
            <contact>
              <ode>
                <kp>1e+06</kp>
                <kd>1</kd>
              </ode>
            </contact>
            <friction>
              <ode>
                <mu>0.5</mu>
                <mu2>0.5</mu2>
              </ode>
              <torsional>
                <ode/>
              </torsional>
            </friction>
            <bounce/>
          </surface>
          <max_contacts>10</max_contacts>
        </collision>
        <visual name='/wheel0_link_visual'>
          <pose frame=''>0 0 0 0 -0 0</pose>
          <geometry>
            <cylinder>
              <length>0.16</length>
              <radius>0.2</radius>
            </cylinder>
          </geometry>
          <material>
            <script>
              <name>Gazebo/Black</name>
              <uri>file://media/materials/scripts/gazebo.material</uri>
            </script>
          </material>
        </visual>
        <gravity>1</gravity>
        <velocity_decay/>
        <self_collide>0</self_collide>
        <enable_wind>0</enable_wind>
        <kinematic>0</kinematic>
      </link>
      <joint name='/wheel0' type='revolute'>
        <child>/wheel0_link</child>
        <parent>/leg0</parent>
        <axis>
          <xyz>0 1 0</xyz>
          <limit>
            <lower>-1e+16</lower>
            <upper>1e+16</upper>
          </limit>
          <dynamics>
            <spring_reference>0</spring_reference>
            <spring_stiffness>0</spring_stiffness>
          </dynamics>
          <use_parent_model_frame>1</use_parent_model_frame>
        </axis>
      </joint>
      <link name='/leg1'>
        <pose frame=''>0.547 -0.285 0.2 0 -0 0</pose>
        <inertial>
          <pose frame=''>0 0 0 0 -0 0</pose>
          <mass>15.64</mass>
          <inertia>
            <ixx>6.15</ixx>
            <ixy>1.31</ixy>
            <ixz>0.218</ixz>
            <iyy>1.386</iyy>
            <iyz>0.873</iyz>
            <izz>6.098</izz>
          </inertia>
        </inertial>
        <collision name='/leg1_collision'>
          <pose frame=''>0 0 0 0 -0 0</pose>
          <geometry>
            <mesh>
              <scale>1 1 1</scale>
              <uri>/opt/ros/kinetic/share/thorvald_model/meshes/drive_modules/836745-5-DUMMY-MIRROR-RevA.stl</uri>
            </mesh>
          </geometry>
          <max_contacts>10</max_contacts>
          <surface>
            <contact>
              <ode/>
            </contact>
            <bounce/>
            <friction>
              <torsional>
                <ode/>
              </torsional>
              <ode/>
            </friction>
          </surface>
        </collision>
        <visual name='/leg1_visual'>
          <pose frame=''>0 0 0 0 -0 0</pose>
          <geometry>
            <mesh>
              <scale>1 1 1</scale>
              <uri>/opt/ros/kinetic/share/thorvald_model/meshes/drive_modules/836745-5-DUMMY-MIRROR-RevA.stl</uri>
            </mesh>
          </geometry>
        </visual>
        <self_collide>0</self_collide>
        <enable_wind>0</enable_wind>
        <kinematic>0</kinematic>
      </link>
      <joint name='/steering1' type='revolute'>
        <child>/leg1</child>
        <parent>/base_link</parent>
        <axis>
          <xyz>0 0 1</xyz>
          <limit>
            <lower>-1e+16</lower>
            <upper>1e+16</upper>
          </limit>
          <dynamics>
            <spring_reference>0</spring_reference>
            <spring_stiffness>0</spring_stiffness>
          </dynamics>
          <use_parent_model_frame>1</use_parent_model_frame>
        </axis>
      </joint>
      <link name='/wheel1_link'>
        <pose frame=''>0.547 -0.285 0.2 -1.5708 0 0</pose>
        <inertial>
          <pose frame=''>0 0 0 0 -0 0</pose>
          <mass>6</mass>
          <inertia>
            <ixx>0.874</ixx>
            <ixy>0</ixy>
            <ixz>0</ixz>
            <iyy>1.504</iyy>
            <iyz>0</iyz>
            <izz>0.874</izz>
          </inertia>
        </inertial>
        <collision name='/wheel1_link_collision'>
          <pose frame=''>0 0 0 0 -0 0</pose>
          <geometry>
            <cylinder>
              <length>0.16</length>
              <radius>0.2</radius>
            </cylinder>
          </geometry>
          <surface>
            <contact>
              <ode>
                <kp>1e+06</kp>
                <kd>1</kd>
              </ode>
            </contact>
            <friction>
              <ode>
                <mu>0.5</mu>
                <mu2>0.5</mu2>
              </ode>
              <torsional>
                <ode/>
              </torsional>
            </friction>
            <bounce/>
          </surface>
          <max_contacts>10</max_contacts>
        </collision>
        <visual name='/wheel1_link_visual'>
          <pose frame=''>0 0 0 0 -0 0</pose>
          <geometry>
            <cylinder>
              <length>0.16</length>
              <radius>0.2</radius>
            </cylinder>
          </geometry>
          <material>
            <script>
              <name>Gazebo/Black</name>
              <uri>file://media/materials/scripts/gazebo.material</uri>
            </script>
          </material>
        </visual>
        <gravity>1</gravity>
        <velocity_decay/>
        <self_collide>0</self_collide>
        <enable_wind>0</enable_wind>
        <kinematic>0</kinematic>
      </link>
      <joint name='/wheel1' type='revolute'>
        <child>/wheel1_link</child>
        <parent>/leg1</parent>
        <axis>
          <xyz>0 1 0</xyz>
          <limit>
            <lower>-1e+16</lower>
            <upper>1e+16</upper>
          </limit>
          <dynamics>
            <spring_reference>0</spring_reference>
            <spring_stiffness>0</spring_stiffness>
          </dynamics>
          <use_parent_model_frame>1</use_parent_model_frame>
        </axis>
      </joint>
      <link name='/leg2'>
        <pose frame=''>0.547 0.285 0.2 0 -0 0</pose>
        <inertial>
          <pose frame=''>0 0 0 0 -0 0</pose>
          <mass>15.64</mass>
          <inertia>
            <ixx>6.15</ixx>
            <ixy>1.31</ixy>
            <ixz>0.218</ixz>
            <iyy>1.386</iyy>
            <iyz>0.873</iyz>
            <izz>6.098</izz>
          </inertia>
        </inertial>
        <collision name='/leg2_collision'>
          <pose frame=''>0 0 0 0 -0 0</pose>
          <geometry>
            <mesh>
              <scale>1 1 1</scale>
              <uri>/opt/ros/kinetic/share/thorvald_model/meshes/drive_modules/836745-5-DUMMY-RevA.stl</uri>
            </mesh>
          </geometry>
          <max_contacts>10</max_contacts>
          <surface>
            <contact>
              <ode/>
            </contact>
            <bounce/>
            <friction>
              <torsional>
                <ode/>
              </torsional>
              <ode/>
            </friction>
          </surface>
        </collision>
        <visual name='/leg2_visual'>
          <pose frame=''>0 0 0 0 -0 0</pose>
          <geometry>
            <mesh>
              <scale>1 1 1</scale>
              <uri>/opt/ros/kinetic/share/thorvald_model/meshes/drive_modules/836745-5-DUMMY-RevA.stl</uri>
            </mesh>
          </geometry>
        </visual>
        <self_collide>0</self_collide>
        <enable_wind>0</enable_wind>
        <kinematic>0</kinematic>
      </link>
      <joint name='/steering2' type='revolute'>
        <child>/leg2</child>
        <parent>/base_link</parent>
        <axis>
          <xyz>0 0 1</xyz>
          <limit>
            <lower>-1e+16</lower>
            <upper>1e+16</upper>
          </limit>
          <dynamics>
            <spring_reference>0</spring_reference>
            <spring_stiffness>0</spring_stiffness>
          </dynamics>
          <use_parent_model_frame>1</use_parent_model_frame>
        </axis>
      </joint>
      <link name='/wheel2_link'>
        <pose frame=''>0.547 0.285 0.2 -1.5708 0 0</pose>
        <inertial>
          <pose frame=''>0 0 0 0 -0 0</pose>
          <mass>6</mass>
          <inertia>
            <ixx>0.874</ixx>
            <ixy>0</ixy>
            <ixz>0</ixz>
            <iyy>1.504</iyy>
            <iyz>0</iyz>
            <izz>0.874</izz>
          </inertia>
        </inertial>
        <collision name='/wheel2_link_collision'>
          <pose frame=''>0 0 0 0 -0 0</pose>
          <geometry>
            <cylinder>
              <length>0.16</length>
              <radius>0.2</radius>
            </cylinder>
          </geometry>
          <surface>
            <contact>
              <ode>
                <kp>1e+06</kp>
                <kd>1</kd>
              </ode>
            </contact>
            <friction>
              <ode>
                <mu>0.5</mu>
                <mu2>0.5</mu2>
              </ode>
              <torsional>
                <ode/>
              </torsional>
            </friction>
            <bounce/>
          </surface>
          <max_contacts>10</max_contacts>
        </collision>
        <visual name='/wheel2_link_visual'>
          <pose frame=''>0 0 0 0 -0 0</pose>
          <geometry>
            <cylinder>
              <length>0.16</length>
              <radius>0.2</radius>
            </cylinder>
          </geometry>
          <material>
            <script>
              <name>Gazebo/Black</name>
              <uri>file://media/materials/scripts/gazebo.material</uri>
            </script>
          </material>
        </visual>
        <gravity>1</gravity>
        <velocity_decay/>
        <self_collide>0</self_collide>
        <enable_wind>0</enable_wind>
        <kinematic>0</kinematic>
      </link>
      <joint name='/wheel2' type='revolute'>
        <child>/wheel2_link</child>
        <parent>/leg2</parent>
        <axis>
          <xyz>0 1 0</xyz>
          <limit>
            <lower>-1e+16</lower>
            <upper>1e+16</upper>
          </limit>
          <dynamics>
            <spring_reference>0</spring_reference>
            <spring_stiffness>0</spring_stiffness>
          </dynamics>
          <use_parent_model_frame>1</use_parent_model_frame>
        </axis>
      </joint>
      <link name='/leg3'>
        <pose frame=''>-0.547 0.285 0.2 0 -0 0</pose>
        <inertial>
          <pose frame=''>0 0 0 0 -0 0</pose>
          <mass>15.64</mass>
          <inertia>
            <ixx>6.15</ixx>
            <ixy>1.31</ixy>
            <ixz>0.218</ixz>
            <iyy>1.386</iyy>
            <iyz>0.873</iyz>
            <izz>6.098</izz>
          </inertia>
        </inertial>
        <collision name='/leg3_collision'>
          <pose frame=''>0 0 0 0 -0 -3.14159</pose>
          <geometry>
            <mesh>
              <scale>1 1 1</scale>
              <uri>/opt/ros/kinetic/share/thorvald_model/meshes/drive_modules/836745-5-DUMMY-MIRROR-RevA.stl</uri>
            </mesh>
          </geometry>
          <max_contacts>10</max_contacts>
          <surface>
            <contact>
              <ode/>
            </contact>
            <bounce/>
            <friction>
              <torsional>
                <ode/>
              </torsional>
              <ode/>
            </friction>
          </surface>
        </collision>
        <visual name='/leg3_visual'>
          <pose frame=''>0 0 0 0 -0 -3.14159</pose>
          <geometry>
            <mesh>
              <scale>1 1 1</scale>
              <uri>/opt/ros/kinetic/share/thorvald_model/meshes/drive_modules/836745-5-DUMMY-MIRROR-RevA.stl</uri>
            </mesh>
          </geometry>
        </visual>
        <self_collide>0</self_collide>
        <enable_wind>0</enable_wind>
        <kinematic>0</kinematic>
      </link>
      <joint name='/steering3' type='revolute'>
        <child>/leg3</child>
        <parent>/base_link</parent>
        <axis>
          <xyz>0 0 1</xyz>
          <limit>
            <lower>-1e+16</lower>
            <upper>1e+16</upper>
          </limit>
          <dynamics>
            <spring_reference>0</spring_reference>
            <spring_stiffness>0</spring_stiffness>
          </dynamics>
          <use_parent_model_frame>1</use_parent_model_frame>
        </axis>
      </joint>
      <link name='/wheel3_link'>
        <pose frame=''>-0.547 0.285 0.2 -1.5708 0 0</pose>
        <inertial>
          <pose frame=''>0 0 0 0 -0 0</pose>
          <mass>6</mass>
          <inertia>
            <ixx>0.874</ixx>
            <ixy>0</ixy>
            <ixz>0</ixz>
            <iyy>1.504</iyy>
            <iyz>0</iyz>
            <izz>0.874</izz>
          </inertia>
        </inertial>
        <collision name='/wheel3_link_collision'>
          <pose frame=''>0 0 0 0 -0 0</pose>
          <geometry>
            <cylinder>
              <length>0.16</length>
              <radius>0.2</radius>
            </cylinder>
          </geometry>
          <surface>
            <contact>
              <ode>
                <kp>1e+06</kp>
                <kd>1</kd>
              </ode>
            </contact>
            <friction>
              <ode>
                <mu>0.5</mu>
                <mu2>0.5</mu2>
              </ode>
              <torsional>
                <ode/>
              </torsional>
            </friction>
            <bounce/>
          </surface>
          <max_contacts>10</max_contacts>
        </collision>
        <visual name='/wheel3_link_visual'>
          <pose frame=''>0 0 0 0 -0 0</pose>
          <geometry>
            <cylinder>
              <length>0.16</length>
              <radius>0.2</radius>
            </cylinder>
          </geometry>
          <material>
            <script>
              <name>Gazebo/Black</name>
              <uri>file://media/materials/scripts/gazebo.material</uri>
            </script>
          </material>
        </visual>
        <gravity>1</gravity>
        <velocity_decay/>
        <self_collide>0</self_collide>
        <enable_wind>0</enable_wind>
        <kinematic>0</kinematic>
      </link>
      <joint name='/wheel3' type='revolute'>
        <child>/wheel3_link</child>
        <parent>/leg3</parent>
        <axis>
          <xyz>0 1 0</xyz>
          <limit>
            <lower>-1e+16</lower>
            <upper>1e+16</upper>
          </limit>
          <dynamics>
            <spring_reference>0</spring_reference>
            <spring_stiffness>0</spring_stiffness>
          </dynamics>
          <use_parent_model_frame>1</use_parent_model_frame>
        </axis>
      </joint>
      <static>0</static>
      <plugin name='_thorvald_gazebo_plugins' filename='libthorvald_gazebo_plugins.so'>
        <alwaysOn>true</alwaysOn>
        <updateRate>20</updateRate>
        <robotNamespace/>
        <commandTopic>base_state</commandTopic>
        <odometryTopic>odometry/gazebo</odometryTopic>
        <odometryFrame>/odom</odometryFrame>
        <robotBaseFrame>/base_link</robotBaseFrame>
        <steering0>/steering0</steering0>
        <steering1>/steering1</steering1>
        <steering2>/steering2</steering2>
        <steering3>/steering3</steering3>
        <steering4>/steering4</steering4>
        <steering5>/steering5</steering5>
        <steering6>/steering6</steering6>
        <steering7>/steering7</steering7>
        <steering8>/steering8</steering8>
        <steering9>/steering9</steering9>
        <steering10>s/teering10</steering10>
        <wheel0>/wheel0</wheel0>
        <wheel1>/wheel1</wheel1>
        <wheel2>/wheel2</wheel2>
        <wheel3>/wheel3</wheel3>
        <wheel4>/wheel4</wheel4>
        <wheel5>/wheel5</wheel5>
        <wheel6>/wheel6</wheel6>
        <wheel7>/wheel7</wheel7>
        <wheel8>/wheel8</wheel8>
        <wheel9>/wheel9</wheel9>
        <wheel10>/wheel10</wheel10>
      </plugin>
      <pose frame=''>0 0 0 0 -0 0</pose>
    </model>
  </world>
</sdf>
